<?xml version="1.0" encoding="utf-8"?><testsuites><testsuite name="pytest" errors="2" failures="0" skipped="0" tests="2" time="0.146" timestamp="2022-11-28T20:23:34.945745" hostname="LAPTOP-I0MC04RM"><testcase classname="" name="tests.test_sum" time="0.000"><error message="collection failure">../../.mooc-software-testing-python/lib/python3.8/site-packages/_pytest/python.py:618: in _importtestmodule
    mod = import_path(self.path, mode=importmode, root=self.config.rootpath)
../../.mooc-software-testing-python/lib/python3.8/site-packages/_pytest/pathlib.py:533: in import_path
    importlib.import_module(module_name)
/usr/lib/python3.8/importlib/__init__.py:127: in import_module
    return _bootstrap._gcd_import(name[level:], package, level)
&lt;frozen importlib._bootstrap&gt;:1014: in _gcd_import
    ???
&lt;frozen importlib._bootstrap&gt;:991: in _find_and_load
    ???
&lt;frozen importlib._bootstrap&gt;:975: in _find_and_load_unlocked
    ???
&lt;frozen importlib._bootstrap&gt;:671: in _load_unlocked
    ???
../../.mooc-software-testing-python/lib/python3.8/site-packages/_pytest/assertion/rewrite.py:159: in exec_module
    source_stat, co = _rewrite_test(fn, self.config)
../../.mooc-software-testing-python/lib/python3.8/site-packages/_pytest/assertion/rewrite.py:337: in _rewrite_test
    tree = ast.parse(source, filename=strfn)
/usr/lib/python3.8/ast.py:47: in parse
    return compile(source, filename, mode, flags,
E     File "/home/janvandenbrand/repos/mooc-software-testing-python/tests/test_sum.py", line 12
E       @pytest.param(
E       ^
E   SyntaxError: invalid syntax</error></testcase><testcase classname="pytest" name="internal" time="0.000"><error message="internal error">Traceback (most recent call last):
  File "/home/janvandenbrand/.mooc-software-testing-python/lib/python3.8/site-packages/_pytest/main.py", line 270, in wrap_session
    session.exitstatus = doit(config, session) or 0
  File "/home/janvandenbrand/.mooc-software-testing-python/lib/python3.8/site-packages/_pytest/main.py", line 323, in _main
    config.hook.pytest_collection(session=session)
  File "/home/janvandenbrand/.mooc-software-testing-python/lib/python3.8/site-packages/pluggy/_hooks.py", line 265, in __call__
    return self._hookexec(self.name, self.get_hookimpls(), kwargs, firstresult)
  File "/home/janvandenbrand/.mooc-software-testing-python/lib/python3.8/site-packages/pluggy/_manager.py", line 80, in _hookexec
    return self._inner_hookexec(hook_name, methods, kwargs, firstresult)
  File "/home/janvandenbrand/.mooc-software-testing-python/lib/python3.8/site-packages/pluggy/_callers.py", line 60, in _multicall
    return outcome.get_result()
  File "/home/janvandenbrand/.mooc-software-testing-python/lib/python3.8/site-packages/pluggy/_result.py", line 60, in get_result
    raise ex[1].with_traceback(ex[2])
  File "/home/janvandenbrand/.mooc-software-testing-python/lib/python3.8/site-packages/pluggy/_callers.py", line 39, in _multicall
    res = hook_impl.function(*args)
  File "/home/janvandenbrand/.mooc-software-testing-python/lib/python3.8/site-packages/_pytest/main.py", line 334, in pytest_collection
    session.perform_collect()
  File "/home/janvandenbrand/.mooc-software-testing-python/lib/python3.8/site-packages/_pytest/main.py", line 666, in perform_collect
    self.config.pluginmanager.check_pending()
  File "/home/janvandenbrand/.mooc-software-testing-python/lib/python3.8/site-packages/pluggy/_manager.py", line 262, in check_pending
    raise PluginValidationError(
pluggy._manager.PluginValidationError: unknown hook 'pytest_warning_captured' in plugin &lt;module 'pytest_azurepipelines' from '/home/janvandenbrand/.mooc-software-testing-python/lib/python3.8/site-packages/pytest_azurepipelines.py'&gt;</error></testcase></testsuite></testsuites>